Workbook
Name Dilimleyici_İŞİN_DURUMU21111111: #N/A
Name Dilimleyici_İŞİN_DURUMU211111111: #N/A
Name Dilimleyici_İŞİN_TÜRÜ1111111: #N/A
Name Dilimleyici_İŞİN_TÜRÜ11111111: #N/A
Name Dilimleyici_MÜŞTERİ_ADI11111111: #N/A
Name Dilimleyici_MÜŞTERİ_ADI111111111: #N/A
Name Dilimleyici_ÖDENME_DURUMU21111111: #N/A
Name Dilimleyici_ÖDENME_DURUMU211111111: #N/A
Name DolarKuru: [1]Ürünlerim!$G$2
Name EuroKuru: [1]Ürünlerim!$G$3
Name Lst_Banka_Kasa: [2]!Tbl_Banka_Kasa[Banka-Kasa]
Name Lst_Bankalarım: [3]!Tablo134[Banka Adı]
Name Lst_Cariler: [1]!Tablo3[Cari Adı]
Name lst_EmlakTipi: [4]!tbl_ayar_EmlakTipi[Emlak Tipi]
Name Lst_Maliye_Kategorileri: OFFSET([2]Pvt_Listeler!$A$3,1,0,COUNTA([2]Pvt_Listeler!$A:$A)-1,1)
Name Lst_Müşteriler: [3]!Tablo1[Firma Adı]
Name Lst_Nakit_Vadeli: [1]!Tablo13[Nakit / Vadeli Seçimi]
Name Lst_Ödeme_Yön: [2]!Tbl_Ödeme_Yön[Ödeme Yöntemi]
Name Lst_ÖdemeDurumu: [3]!Tablo1345[Ödeme Durumu]
Name lst_Satılık_Kiralık: [4]!tbl_ayar_Satılık[Satılık/Kiralık]
Name Lst_Satış_Per: [5]!Tablo2[Ad Soyad]
Name Lst_SatışPer: #REF!
Name Lst_Servis: [2]!Tbl_Sektör_Kategori[Servis]
Name Lst_Tedarikçiler: [3]!Tablo13[Firma Adı]
Name Lst_TümHisseler: [6]!TÜM_HİSSELER_1[Menkul]
Name Lst_Ürün_Ailesi: [2]!Tbl_Ürün_Ailesi[Ürün Ailesi]
Name Lst_Ürünler: [1]!Tablo4[Ürün Adı]
Name Lst_Ürünlerim: [7]!Tablo2[Ürün Adı]
Name Lst_VergiOranları: [3]!Tablo13456[Vergi Oranları]
Name Lst_Yıl_Ay: [2]!Tablo8[Tarihler]
Name MailBody1: [8]AnaSayfa!$C$9
Name MailBody2: [8]AnaSayfa!$C$10
Name MailBody3: [8]AnaSayfa!$C$11
Name MailBody4: [8]AnaSayfa!$C$12
Name MailBody5: [8]AnaSayfa!$C$13
Name MailBodyHello: [8]AnaSayfa!$C$8
Name MailSign: [8]AnaSayfa!$C$14
Name oran: [9]Ürün_Fiyat_Listesi!$E$3
Name rng_arama: FATURALAR!#REF!

Sheet DONE
H1: FATURALAR SAYFASI İÇİN
B2: MÜSTERİ ID | C2: MÜŞTERİLER GELEN İŞLER | D2: MÜŞTERİLER GİDEN İŞLER | E2: İŞİN TÜRÜ | F2: İŞİN DURUMU | G2: ÖDENME DURUMU | H2: FATURA TİPİ | I2: VERGİ ORANI | J2: ÖDEME DURUMU
B3: MUS1001 | E3: EKB ÇİZİM VE ONAYI | F3: TESLİM EDİLDİ | G3: ÖDEME ALINDI | H3: E-ARŞİV | I3: 0.01 | J3: Ödeme Bekleniyor
B4: MUS1002 | E4: EKB ÇİZİMİ | F4: DEVAM EDİYOR | G4: ÖDENMEDİ | H4: E-FATURA | I4: 0.1 | J4: Ödeme Tamamlandı
B5: MUS1003 | E5: EKB ONAYI | F5: İPTAL EDİLDİ | H5: Z RAPORU | I5: 0.2 | J5: Fatura Kesilecek
B6: MUS1004 | E6: ÖN HESAP SONUÇ FORMU | F6: BEKLEMEDE
B7: MUS1005 | E7: AKUSTİK RAPOR & PROJE
B8: MUS1006 | E8: 3BSYM
B9: MUS1007
B10: MUS1008
B11: MUS1009
B12: MUS1010
B13: MUS1011
B14: MUS1012
B15: MUS1013
B16: MUS1014
B17: MUS1015
B18: MUS1016
B19: MUS1017
B20: MUS1018
... B112: MUS1110

Sheet ANA SAYFA

Sheet FATURALAR
B2: Gelir Faturalarım | E2: PLANAKS MÜHENDİSLİK MİMARLIK İNŞAAT PEYZAJ EMLAK SANAYİ VE TİCARET LİMİTED ŞİRKETİ
B5: Fatura Tarihi | C5: Fatura Tipi | D5: Fatura No | E5: Vergi Numarası | F5: Müşteri Adı | G5: Hizmet Tutarı | H5: Vergi Oranı (KDV) | I5: Fatura Tutarı | J5: Ödenme Durumu | K5: Notlar
J6: Ödeme Bekleniyor
J7: Ödeme Bekleniyor
J8: Ödeme Tamamlandı
J9: Ödeme Bekleniyor
J10: Ödeme Tamamlandı
J11: Ödeme Tamamlandı | K11: KREDİ KARTI
J12: Ödeme Tamamlandı | K12: KREDİ KARTI
J13: Ödeme Tamamlandı | K13: 2400 ₺ ÖDENECEK
J14: Ödeme Tamamlandı | K14: KREDİ KARTI
J15: Ödeme Tamamlandı
J16: Ödeme Tamamlandı
J17: Ödeme Tamamlandı
J18: Ödeme Bekleniyor
J19: Ödeme Tamamlandı
J20: Ödeme Tamamlandı
G42: =SUBTOTAL(109,Tablo43[Hizmet Tutarı]) -> 0 | H42: =SUBTOTAL(109,Tablo43[Vergi Oranı (KDV)]) -> 0 | I42: =SUBTOTAL(109,Tablo43[Fatura Tutarı]) -> 0

Sheet GELİR İCMAL
A1: PLANAKS MÜHENDİSLİK MİMARLIK İNŞAAT PEYZAJ EMLAK SANAYİ VE TİCARET LİMİTED ŞİRKETİ CARİ HESAP TAKİBİ (GELEN İŞLER) | Q1: KALAN ÖDEME KONTROLÜ
A2: MÜŞTERİ ADI | B2: 46023 | C2: 46054 | D2: 46082 | E2: 46113 | F2: 46143 | G2: 46174 | H2: 46204 | I2: 46235 | J2: 46266 | K2: 46296 | L2: 46327 | M2: 46357 | N2: TOPLAM BORÇ | O2: ALINAN ÖDEME | P2: KALAN ÖDEME | Q2: 45292 | R2: 45323 | S2: 45352 | T2: 45748 | U2: 45778 | V2: 45809 | W2: 45839 | X2: 45870 | Y2: 45901 | Z2: 45931 | AA2: 45962 | AB2: 45992
A3: UMUT ARSLAN | B3: =+SUMIFS(Tablo1710612131618202224[SATIŞ TUTARI],Tablo1710612131618202224[TARİH],">=01/01/2026",Tablo1710612131618202224[TARİH],"<=31/01/2026",Tablo1710612131618202224[MÜŞTERİ ADI],'GELİR İCMAL'!A3) -> 0 | C3: =+SUMIFS(Tablo1710612131618202224[SATIŞ TUTARI],Tablo1710612131618202224[TARİH],">=01/02/2026",Tablo1710612131618202224[TARİH],"<=28/02/2026",Tablo1710612131618202224[MÜŞTERİ ADI],'GELİR İCMAL'!A3) -> 0 | N3: =+SUM(B3:M3) -> 0 | P3: =+N3-O3 -> 0
A4: ÇAĞLAYAN BODUR | B4: =+SUMIFS(Tablo1710612131618202224[SATIŞ TUTARI],Tablo1710612131618202224[TARİH],">=01/01/2026",Tablo1710612131618202224[TARİH],"<=31/01/2026",Tablo1710612131618202224[MÜŞTERİ ADI],'GELİR İCMAL'!A4) -> 0 | C4: =+SUMIFS(Tablo1710612131618202224[SATIŞ TUTARI],Tablo1710612131618202224[TARİH],">=01/02/2026",Tablo1710612131618202224[TARİH],"<=28/02/2026",Tablo1710612131618202224[MÜŞTERİ ADI],'GELİR İCMAL'!A4) -> 0 | N4: =+SUM(B4:M4) -> 0 | P4: =+N4-O4 -> 0 | AC4: ŞUBAT AYININ CARİSİ 15/02/2026 DA ÖDENECEK
A5: MUHAMMET BAHÇECİ | B5: =+SUMIFS(Tablo1710612131618202224[SATIŞ TUTARI],Tablo1710612131618202224[TARİH],">=01/01/2026",Tablo1710612131618202224[TARİH],"<=31/01/2026",Tablo1710612131618202224[MÜŞTERİ ADI],'GELİR İCMAL'!A5) -> 0 | C5: =+SUMIFS(Tablo1710612131618202224[SATIŞ TUTARI],Tablo1710612131618202224[TARİH],">=01/02/2026",Tablo1710612131618202224[TARİH],"<=28/02/2026",Tablo1710612131618202224[MÜŞTERİ ADI],'GELİR İCMAL'!A5) -> 0 | N5: =+SUM(B5:M5) -> 0 | P5: =+N5-O5 -> 0
A6: SELÇUK KARABULUT | B6: =+SUMIFS(Tablo1710612131618202224[SATIŞ TUTARI],Tablo1710612131618202224[TARİH],">=01/01/2026",Tablo1710612131618202224[TARİH],"<=31/01/2026",Tablo1710612131618202224[MÜŞTERİ ADI],'GELİR İCMAL'!A6) -> 0 | C6: =+SUMIFS(Tablo1710612131618202224[SATIŞ TUTARI],Tablo1710612131618202224[TARİH],">=01/02/2026",Tablo1710612131618202224[TARİH],"<=28/02/2026",Tablo1710612131618202224[MÜŞTERİ ADI],'GELİR İCMAL'!A6) -> 0 | N6: =+SUM(B6:M6) -> 0 | P6: =+N6-O6 -> 0
A7: BURAK ORAL | B7: =+SUMIFS(Tablo1710612131618202224[SATIŞ TUTARI],Tablo1710612131618202224[TARİH],">=01/01/2026",Tablo1710612131618202224[TARİH],"<=31/01/2026",Tablo1710612131618202224[MÜŞTERİ ADI],'GELİR İCMAL'!A7) -> 0 | C7: =+SUMIFS(Tablo1710612131618202224[SATIŞ TUTARI],Tablo1710612131618202224[TARİH],">=01/02/2026",Tablo1710612131618202224[TARİH],"<=28/02/2026",Tablo1710612131618202224[MÜŞTERİ ADI],'GELİR İCMAL'!A7) -> 0 | N7: =+SUM(B7:M7) -> 0 | P7: =+N7-O7 -> 0
A8: ERDAL ÖNCEL | B8: =+SUMIFS(Tablo1710612131618202224[SATIŞ TUTARI],Tablo1710612131618202224[TARİH],">=01/01/2026",Tablo1710612131618202224[TARİH],"<=31/01/2026",Tablo1710612131618202224[MÜŞTERİ ADI],'GELİR İCMAL'!A8) -> 0 | C8: =+SUMIFS(Tablo1710612131618202224[SATIŞ TUTARI],Tablo1710612131618202224[TARİH],">=01/02/2026",Tablo1710612131618202224[TARİH],"<=28/02/2026",Tablo1710612131618202224[MÜŞTERİ ADI],'GELİR İCMAL'!A8) -> 0 | N8: =+SUM(B8:M8) -> 0 | P8: =+N8-O8 -> 0
A9: FATMA CEYDA COŞKUN | B9: =+SUMIFS(Tablo1710612131618202224[SATIŞ TUTARI],Tablo1710612131618202224[TARİH],">=01/01/2026",Tablo1710612131618202224[TARİH],"<=31/01/2026",Tablo1710612131618202224[MÜŞTERİ ADI],'GELİR İCMAL'!A9) -> 0 | C9: =+SUMIFS(Tablo1710612131618202224[SATIŞ TUTARI],Tablo1710612131618202224[TARİH],">=01/02/2026",Tablo1710612131618202224[TARİH],"<=28/02/2026",Tablo1710612131618202224[MÜŞTERİ ADI],'GELİR İCMAL'!A9) -> 0 | N9: =+SUM(B9:M9) -> 0 | P9: =+N9-O9 -> 0
A10: FURKAN ŞAHAN | B10: =+SUMIFS(Tablo1710612131618202224[SATIŞ TUTARI],Tablo1710612131618202224[TARİH],">=01/01/2026",Tablo1710612131618202224[TARİH],"<=31/01/2026",Tablo1710612131618202224[MÜŞTERİ ADI],'GELİR İCMAL'!A10) -> 0 | C10: =+SUMIFS(Tablo1710612131618202224[SATIŞ TUTARI],Tablo1710612131618202224[TARİH],">=01/02/2026",Tablo1710612131618202224[TARİH],"<=28/02/2026",Tablo1710612131618202224[MÜŞTERİ ADI],'GELİR İCMAL'!A10) -> 0 | N10: =+SUM(B10:M10) -> 0 | P10: =+N10-O10 -> 0
A11: GEZEGEN ASANSÖR | B11: =+SUMIFS(Tablo1710612131618202224[SATIŞ TUTARI],Tablo1710612131618202224[TARİH],">=01/01/2026",Tablo1710612131618202224[TARİH],"<=31/01/2026",Tablo1710612131618202224[MÜŞTERİ ADI],'GELİR İCMAL'!A11) -> 0 | C11: =+SUMIFS(Tablo1710612131618202224[SATIŞ TUTARI],Tablo1710612131618202224[TARİH],">=01/02/2026",Tablo1710612131618202224[TARİH],"<=28/02/2026",Tablo1710612131618202224[MÜŞTERİ ADI],'GELİR İCMAL'!A11) -> 0 | N11: =+SUM(B11:M11) -> 0 | P11: =+N11-O11 -> 0
A12: HASAN TAŞDEMİR | B12: =+SUMIFS(Tablo1710612131618202224[SATIŞ TUTARI],Tablo1710612131618202224[TARİH],">=01/01/2026",Tablo1710612131618202224[TARİH],"<=31/01/2026",Tablo1710612131618202224[MÜŞTERİ ADI],'GELİR İCMAL'!A12) -> 0 | C12: =+SUMIFS(Tablo1710612131618202224[SATIŞ TUTARI],Tablo1710612131618202224[TARİH],">=01/02/2026",Tablo1710612131618202224[TARİH],"<=28/02/2026",Tablo1710612131618202224[MÜŞTERİ ADI],'GELİR İCMAL'!A12) -> 0 | N12: =+SUM(B12:M12) -> 0 | P12: =+N12-O12 -> 0
A13: NİDA KÜSMÜŞ | B13: =+SUMIFS(Tablo1710612131618202224[SATIŞ TUTARI],Tablo1710612131618202224[TARİH],">=01/01/2026",Tablo1710612131618202224[TARİH],"<=31/01/2026",Tablo1710612131618202224[MÜŞTERİ ADI],'GELİR İCMAL'!A13) -> 0 | C13: =+SUMIFS(Tablo1710612131618202224[SATIŞ TUTARI],Tablo1710612131618202224[TARİH],">=01/02/2026",Tablo1710612131618202224[TARİH],"<=28/02/2026",Tablo1710612131618202224[MÜŞTERİ ADI],'GELİR İCMAL'!A13) -> 0 | N13: =+SUM(B13:M13) -> 0 | P13: =+N13-O13 -> 0
A14: ŞAFAK YAĞAN | B14: =+SUMIFS(Tablo1710612131618202224[SATIŞ TUTARI],Tablo1710612131618202224[TARİH],">=01/01/2026",Tablo1710612131618202224[TARİH],"<=31/01/2026",Tablo1710612131618202224[MÜŞTERİ ADI],'GELİR İCMAL'!A14) -> 0 | C14: =+SUMIFS(Tablo1710612131618202224[SATIŞ TUTARI],Tablo1710612131618202224[TARİH],">=01/02/2026",Tablo1710612131618202224[TARİH],"<=28/02/2026",Tablo1710612131618202224[MÜŞTERİ ADI],'GELİR İCMAL'!A14) -> 0 | N14: =+SUM(B14:M14) -> 0 | P14: =+N14-O14 -> 0
A15: UĞUR YILMAZEL | B15: =+SUMIFS(Tablo1710612131618202224[SATIŞ TUTARI],Tablo1710612131618202224[TARİH],">=01/01/2026",Tablo1710612131618202224[TARİH],"<=31/01/2026",Tablo1710612131618202224[MÜŞTERİ ADI],'GELİR İCMAL'!A15) -> 0 | C15: =+SUMIFS(Tablo1710612131618202224[SATIŞ TUTARI],Tablo1710612131618202224[TARİH],">=01/02/2026",Tablo1710612131618202224[TARİH],"<=28/02/2026",Tablo1710612131618202224[MÜŞTERİ ADI],'GELİR İCMAL'!A15) -> 0 | N15: =+SUM(B15:M15) -> 0 | P15: =+N15-O15 -> 0
A16: HASAN DURUCAN | B16: =+SUMIFS(Tablo1710612131618202224[SATIŞ TUTARI],Tablo1710612131618202224[TARİH],">=01/01/2026",Tablo1710612131618202224[TARİH],"<=31/01/2026",Tablo1710612131618202224[MÜŞTERİ ADI],'GELİR İCMAL'!A16) -> 0 | C16: =+SUMIFS(Tablo1710612131618202224[SATIŞ TUTARI],Tablo1710612131618202224[TARİH],">=01/02/2026",Tablo1710612131618202224[TARİH],"<=28/02/2026",Tablo1710612131618202224[MÜŞTERİ ADI],'GELİR İCMAL'!A16) -> 0 | N16: =+SUM(B16:M16) -> 0 | P16: =+N16-O16 -> 0
... A81: ONUR BEY HARİTACI | B81: =+SUMIFS(Tablo1710612131618202224[SATIŞ TUTARI],Tablo1710612131618202224[TARİH],">=01/01/2026",Tablo1710612131618202224[TARİH],"<=31/01/2026",Tablo1710612131618202224[MÜŞTERİ ADI],'GELİR İCMAL'!A81) -> 0 | C81: =+SUMIFS(Tablo1710612131618202224[SATIŞ TUTARI],Tablo1710612131618202224[TARİH],">=01/02/2026",Tablo1710612131618202224[TARİH],"<=28/02/2026",Tablo1710612131618202224[MÜŞTERİ ADI],'GELİR İCMAL'!A81) -> 0 | N81: =+SUM(B81:M81) -> 0 | P81: =+N81-O81 -> 0
B82: =+SUMIFS(Tablo1710612131618202224[SATIŞ TUTARI],Tablo1710612131618202224[TARİH],">=01/01/2026",Tablo1710612131618202224[TARİH],"<=31/01/2026",Tablo1710612131618202224[MÜŞTERİ ADI],'GELİR İCMAL'!A82) -> 0 | C82: =+SUMIFS(Tablo1710612131618202224[SATIŞ TUTARI],Tablo1710612131618202224[TARİH],">=01/02/2026",Tablo1710612131618202224[TARİH],"<=28/02/2026",Tablo1710612131618202224[MÜŞTERİ ADI],'GELİR İCMAL'!A82) -> 0 | N82: =+SUM(B82:M82) -> 0 | P82: =+N82-O82 -> 0
B83: =+SUMIFS(Tablo1710612131618202224[SATIŞ TUTARI],Tablo1710612131618202224[TARİH],">=01/01/2026",Tablo1710612131618202224[TARİH],"<=31/01/2026",Tablo1710612131618202224[MÜŞTERİ ADI],'GELİR İCMAL'!A83) -> 0 | C83: =+SUMIFS(Tablo1710612131618202224[SATIŞ TUTARI],Tablo1710612131618202224[TARİH],">=01/02/2026",Tablo1710612131618202224[TARİH],"<=28/02/2026",Tablo1710612131618202224[MÜŞTERİ ADI],'GELİR İCMAL'!A83) -> 0 | N83: =+SUM(B83:M83) -> 0 | P83: =+N83-O83 -> 0
B84: =+SUMIFS(Tablo1710612131618202224[SATIŞ TUTARI],Tablo1710612131618202224[TARİH],">=01/01/2026",Tablo1710612131618202224[TARİH],"<=31/01/2026",Tablo1710612131618202224[MÜŞTERİ ADI],'GELİR İCMAL'!A84) -> 0 | C84: =+SUMIFS(Tablo1710612131618202224[SATIŞ TUTARI],Tablo1710612131618202224[TARİH],">=01/02/2026",Tablo1710612131618202224[TARİH],"<=28/02/2026",Tablo1710612131618202224[MÜŞTERİ ADI],'GELİR İCMAL'!A84) -> 0 | N84: =+SUM(B84:M84) -> 0 | P84: =+N84-O84 -> 0
B85: =+SUMIFS(Tablo1710612131618202224[SATIŞ TUTARI],Tablo1710612131618202224[TARİH],">=01/01/2026",Tablo1710612131618202224[TARİH],"<=31/01/2026",Tablo1710612131618202224[MÜŞTERİ ADI],'GELİR İCMAL'!A85) -> 0 | C85: =+SUMIFS(Tablo1710612131618202224[SATIŞ TUTARI],Tablo1710612131618202224[TARİH],">=01/02/2026",Tablo1710612131618202224[TARİH],"<=28/02/2026",Tablo1710612131618202224[MÜŞTERİ ADI],'GELİR İCMAL'!A85) -> 0 | N85: =+SUM(B85:M85) -> 0 | P85: =+N85-O85 -> 0
B86: =+SUMIFS(Tablo1710612131618202224[SATIŞ TUTARI],Tablo1710612131618202224[TARİH],">=01/01/2026",Tablo1710612131618202224[TARİH],"<=31/01/2026",Tablo1710612131618202224[MÜŞTERİ ADI],'GELİR İCMAL'!A86) -> 0 | C86: =+SUMIFS(Tablo1710612131618202224[SATIŞ TUTARI],Tablo1710612131618202224[TARİH],">=01/02/2026",Tablo1710612131618202224[TARİH],"<=28/02/2026",Tablo1710612131618202224[MÜŞTERİ ADI],'GELİR İCMAL'!A86) -> 0 | N86: =+SUM(B86:M86) -> 0 | P86: =+N86-O86 -> 0
B87: =+SUMIFS(Tablo1710612131618202224[SATIŞ TUTARI],Tablo1710612131618202224[TARİH],">=01/01/2026",Tablo1710612131618202224[TARİH],"<=31/01/2026",Tablo1710612131618202224[MÜŞTERİ ADI],'GELİR İCMAL'!A87) -> 0 | C87: =+SUMIFS(Tablo1710612131618202224[SATIŞ TUTARI],Tablo1710612131618202224[TARİH],">=01/02/2026",Tablo1710612131618202224[TARİH],"<=28/02/2026",Tablo1710612131618202224[MÜŞTERİ ADI],'GELİR İCMAL'!A87) -> 0 | N87: =+SUM(B87:M87) -> 0 | P87: =+N87-O87 -> 0
B88: =+SUMIFS(Tablo1710612131618202224[SATIŞ TUTARI],Tablo1710612131618202224[TARİH],">=01/01/2026",Tablo1710612131618202224[TARİH],"<=31/01/2026",Tablo1710612131618202224[MÜŞTERİ ADI],'GELİR İCMAL'!A88) -> 0 | C88: =+SUMIFS(Tablo1710612131618202224[SATIŞ TUTARI],Tablo1710612131618202224[TARİH],">=01/02/2026",Tablo1710612131618202224[TARİH],"<=28/02/2026",Tablo1710612131618202224[MÜŞTERİ ADI],'GELİR İCMAL'!A88) -> 0 | N88: =+SUM(B88:M88) -> 0 | P88: =+N88-O88 -> 0
B89: =+SUMIFS(Tablo1710612131618202224[SATIŞ TUTARI],Tablo1710612131618202224[TARİH],">=01/01/2026",Tablo1710612131618202224[TARİH],"<=31/01/2026",Tablo1710612131618202224[MÜŞTERİ ADI],'GELİR İCMAL'!A89) -> 0 | C89: =+SUMIFS(Tablo1710612131618202224[SATIŞ TUTARI],Tablo1710612131618202224[TARİH],">=01/02/2026",Tablo1710612131618202224[TARİH],"<=28/02/2026",Tablo1710612131618202224[MÜŞTERİ ADI],'GELİR İCMAL'!A89) -> 0 | N89: =+SUM(B89:M89) -> 0 | P89: =+N89-O89 -> 0
B90: =+SUMIFS(Tablo1710612131618202224[SATIŞ TUTARI],Tablo1710612131618202224[TARİH],">=01/01/2026",Tablo1710612131618202224[TARİH],"<=31/01/2026",Tablo1710612131618202224[MÜŞTERİ ADI],'GELİR İCMAL'!A90) -> 0 | C90: =+SUMIFS(Tablo1710612131618202224[SATIŞ TUTARI],Tablo1710612131618202224[TARİH],">=01/02/2026",Tablo1710612131618202224[TARİH],"<=28/02/2026",Tablo1710612131618202224[MÜŞTERİ ADI],'GELİR İCMAL'!A90) -> 0 | N90: =+SUM(B90:M90) -> 0 | P90: =+N90-O90 -> 0
B91: =+SUMIFS(Tablo1710612131618202224[SATIŞ TUTARI],Tablo1710612131618202224[TARİH],">=01/01/2026",Tablo1710612131618202224[TARİH],"<=31/01/2026",Tablo1710612131618202224[MÜŞTERİ ADI],'GELİR İCMAL'!A91) -> 0 | C91: =+SUMIFS(Tablo1710612131618202224[SATIŞ TUTARI],Tablo1710612131618202224[TARİH],">=01/02/2026",Tablo1710612131618202224[TARİH],"<=28/02/2026",Tablo1710612131618202224[MÜŞTERİ ADI],'GELİR İCMAL'!A91) -> 0 | N91: =+SUM(B91:M91) -> 0 | P91: =+N91-O91 -> 0
B92: =+SUMIFS(Tablo1710612131618202224[SATIŞ TUTARI],Tablo1710612131618202224[TARİH],">=01/01/2026",Tablo1710612131618202224[TARİH],"<=31/01/2026",Tablo1710612131618202224[MÜŞTERİ ADI],'GELİR İCMAL'!A92) -> 0 | C92: =+SUMIFS(Tablo1710612131618202224[SATIŞ TUTARI],Tablo1710612131618202224[TARİH],">=01/02/2026",Tablo1710612131618202224[TARİH],"<=28/02/2026",Tablo1710612131618202224[MÜŞTERİ ADI],'GELİR İCMAL'!A92) -> 0 | N92: =+SUM(B92:M92) -> 0 | P92: =+N92-O92 -> 0
B93: =+SUMIFS(Tablo1710612131618202224[SATIŞ TUTARI],Tablo1710612131618202224[TARİH],">=01/01/2026",Tablo1710612131618202224[TARİH],"<=31/01/2026",Tablo1710612131618202224[MÜŞTERİ ADI],'GELİR İCMAL'!A93) -> 0 | C93: =+SUMIFS(Tablo1710612131618202224[SATIŞ TUTARI],Tablo1710612131618202224[TARİH],">=01/02/2026",Tablo1710612131618202224[TARİH],"<=28/02/2026",Tablo1710612131618202224[MÜŞTERİ ADI],'GELİR İCMAL'!A93) -> 0 | N93: =+SUM(B93:M93) -> 0 | P93: =+N93-O93 -> 0
... B121: =+SUMIFS(Tablo1710612131618202224[SATIŞ TUTARI],Tablo1710612131618202224[TARİH],">=01/01/2026",Tablo1710612131618202224[TARİH],"<=31/01/2026",Tablo1710612131618202224[MÜŞTERİ ADI],'GELİR İCMAL'!A121) -> 0 | C121: =+SUMIFS(Tablo1710612131618202224[SATIŞ TUTARI],Tablo1710612131618202224[TARİH],">=01/02/2026",Tablo1710612131618202224[TARİH],"<=28/02/2026",Tablo1710612131618202224[MÜŞTERİ ADI],'GELİR İCMAL'!A121) -> 0 | N121: =+SUM(B121:M121) -> 0 | P121: =+N121-O121 -> 0
B122: =SUM(B3:B121) -> 0 | C122: =SUM(C3:C121) -> 0 | D122: =SUM(D3:D121) -> 0 | E122: =SUM(E3:E121) -> 0 | F122: =SUM(F3:F121) -> 0 | G122: =SUM(G3:G121) -> 0 | H122: =SUM(H3:H121) -> 0 | I122: =SUM(I3:I121) -> 0 | ... O122: =SUM(O3:O121) -> 0 | P122: =+N122-O122 -> 0 | Q122: =SUM(Q3:Q121) -> 0 | R122: =SUM(R3:R121) -> 0 | S122: =SUM(S3:S121) -> 0 | T122: =SUM(T3:T121) -> 0 | U122: =SUM(U3:U121) -> 0 | V122: =SUM(V3:V121) -> 0 | W122: =SUM(W3:W121) -> 0 | X122: =SUM(X3:X121) -> 0 | ... AB122: =SUM(AB3:AB121) -> 0
P123: =+IF(Q123=P122,"HATA YOK","HATA VAR") -> HATA YOK | Q123: =+SUM(Q122:AB122) -> 0

Sheet GİDER İCMAL
A1: PLANAKS MÜHENDİSLİK MİMARLIK İNŞAAT PEYZAJ EMLAK SANAYİ VE TİCARET LİMİTED ŞİRKETİ CARİ HESAP TAKİBİ (GİDEN İŞLER) | Q1: KALAN ÖDEME KONTROLÜ
A2: MÜŞTERİ ADI | B2: 46023 | C2: 46054 | D2: 46082 | E2: 46113 | F2: 46143 | G2: 46174 | H2: 46204 | I2: 46235 | J2: 46266 | K2: 46296 | L2: 46327 | M2: 46357 | N2: TOPLAM BORÇ | O2: ALINAN ÖDEME | P2: KALAN ÖDEME | Q2: 45292 | R2: 45323 | S2: 45352 | T2: 45748 | U2: 45778 | V2: 45809 | W2: 45839 | X2: 45870 | Y2: 45901 | Z2: 45931 | AA2: 45962 | AB2: 45992
A3: UMUT ARSLAN | B3: =+SUMIFS(Tablo17106121316182022242[SATIŞ TUTARI],Tablo17106121316182022242[TARİH],">=01/01/2026",Tablo17106121316182022242[TARİH],"<=31/01/2026",Tablo17106121316182022242[MÜŞTERİ ADI],'GİDER İCMAL'!A3) -> 0 | C3: =+SUMIFS(Tablo17106121316182022242[SATIŞ TUTARI],Tablo17106121316182022242[TARİH],">=01/02/2026",Tablo17106121316182022242[TARİH],"<=28/02/2026",Tablo17106121316182022242[MÜŞTERİ ADI],'GİDER İCMAL'!A3) -> 0 | N3: =+SUM(B3:M3) -> 0 | P3: =+N3-O3 -> 0
B4: =+SUMIFS(Tablo17106121316182022242[SATIŞ TUTARI],Tablo17106121316182022242[TARİH],">=01/01/2026",Tablo17106121316182022242[TARİH],"<=31/01/2026",Tablo17106121316182022242[MÜŞTERİ ADI],'GİDER İCMAL'!A4) -> 0 | C4: =+SUMIFS(Tablo17106121316182022242[SATIŞ TUTARI],Tablo17106121316182022242[TARİH],">=01/02/2026",Tablo17106121316182022242[TARİH],"<=28/02/2026",Tablo17106121316182022242[MÜŞTERİ ADI],'GİDER İCMAL'!A4) -> 0 | N4: =+SUM(B4:M4) -> 0 | P4: =+N4-O4 -> 0
B5: =+SUMIFS(Tablo17106121316182022242[SATIŞ TUTARI],Tablo17106121316182022242[TARİH],">=01/01/2026",Tablo17106121316182022242[TARİH],"<=31/01/2026",Tablo17106121316182022242[MÜŞTERİ ADI],'GİDER İCMAL'!A5) -> 0 | C5: =+SUMIFS(Tablo17106121316182022242[SATIŞ TUTARI],Tablo17106121316182022242[TARİH],">=01/02/2026",Tablo17106121316182022242[TARİH],"<=28/02/2026",Tablo17106121316182022242[MÜŞTERİ ADI],'GİDER İCMAL'!A5) -> 0 | N5: =+SUM(B5:M5) -> 0 | P5: =+N5-O5 -> 0
B6: =+SUMIFS(Tablo17106121316182022242[SATIŞ TUTARI],Tablo17106121316182022242[TARİH],">=01/01/2026",Tablo17106121316182022242[TARİH],"<=31/01/2026",Tablo17106121316182022242[MÜŞTERİ ADI],'GİDER İCMAL'!A6) -> 0 | C6: =+SUMIFS(Tablo17106121316182022242[SATIŞ TUTARI],Tablo17106121316182022242[TARİH],">=01/02/2026",Tablo17106121316182022242[TARİH],"<=28/02/2026",Tablo17106121316182022242[MÜŞTERİ ADI],'GİDER İCMAL'!A6) -> 0 | N6: =+SUM(B6:M6) -> 0 | P6: =+N6-O6 -> 0
B7: =+SUMIFS(Tablo17106121316182022242[SATIŞ TUTARI],Tablo17106121316182022242[TARİH],">=01/01/2026",Tablo17106121316182022242[TARİH],"<=31/01/2026",Tablo17106121316182022242[MÜŞTERİ ADI],'GİDER İCMAL'!A7) -> 0 | C7: =+SUMIFS(Tablo17106121316182022242[SATIŞ TUTARI],Tablo17106121316182022242[TARİH],">=01/02/2026",Tablo17106121316182022242[TARİH],"<=28/02/2026",Tablo17106121316182022242[MÜŞTERİ ADI],'GİDER İCMAL'!A7) -> 0 | N7: =+SUM(B7:M7) -> 0 | P7: =+N7-O7 -> 0
B8: =+SUMIFS(Tablo17106121316182022242[SATIŞ TUTARI],Tablo17106121316182022242[TARİH],">=01/01/2026",Tablo17106121316182022242[TARİH],"<=31/01/2026",Tablo17106121316182022242[MÜŞTERİ ADI],'GİDER İCMAL'!A8) -> 0 | C8: =+SUMIFS(Tablo17106121316182022242[SATIŞ TUTARI],Tablo17106121316182022242[TARİH],">=01/02/2026",Tablo17106121316182022242[TARİH],"<=28/02/2026",Tablo17106121316182022242[MÜŞTERİ ADI],'GİDER İCMAL'!A8) -> 0 | N8: =+SUM(B8:M8) -> 0 | P8: =+N8-O8 -> 0
B9: =+SUMIFS(Tablo17106121316182022242[SATIŞ TUTARI],Tablo17106121316182022242[TARİH],">=01/01/2026",Tablo17106121316182022242[TARİH],"<=31/01/2026",Tablo17106121316182022242[MÜŞTERİ ADI],'GİDER İCMAL'!A9) -> 0 | C9: =+SUMIFS(Tablo17106121316182022242[SATIŞ TUTARI],Tablo17106121316182022242[TARİH],">=01/02/2026",Tablo17106121316182022242[TARİH],"<=28/02/2026",Tablo17106121316182022242[MÜŞTERİ ADI],'GİDER İCMAL'!A9) -> 0 | N9: =+SUM(B9:M9) -> 0 | P9: =+N9-O9 -> 0
B10: =+SUMIFS(Tablo17106121316182022242[SATIŞ TUTARI],Tablo17106121316182022242[TARİH],">=01/01/2026",Tablo17106121316182022242[TARİH],"<=31/01/2026",Tablo17106121316182022242[MÜŞTERİ ADI],'GİDER İCMAL'!A10) -> 0 | C10: =+SUMIFS(Tablo17106121316182022242[SATIŞ TUTARI],Tablo17106121316182022242[TARİH],">=01/02/2026",Tablo17106121316182022242[TARİH],"<=28/02/2026",Tablo17106121316182022242[MÜŞTERİ ADI],'GİDER İCMAL'!A10) -> 0 | N10: =+SUM(B10:M10) -> 0 | P10: =+N10-O10 -> 0
B11: =+SUMIFS(Tablo17106121316182022242[SATIŞ TUTARI],Tablo17106121316182022242[TARİH],">=01/01/2026",Tablo17106121316182022242[TARİH],"<=31/01/2026",Tablo17106121316182022242[MÜŞTERİ ADI],'GİDER İCMAL'!A11) -> 0 | C11: =+SUMIFS(Tablo17106121316182022242[SATIŞ TUTARI],Tablo17106121316182022242[TARİH],">=01/02/2026",Tablo17106121316182022242[TARİH],"<=28/02/2026",Tablo17106121316182022242[MÜŞTERİ ADI],'GİDER İCMAL'!A11) -> 0 | N11: =+SUM(B11:M11) -> 0 | P11: =+N11-O11 -> 0
B12: =+SUMIFS(Tablo17106121316182022242[SATIŞ TUTARI],Tablo17106121316182022242[TARİH],">=01/01/2026",Tablo17106121316182022242[TARİH],"<=31/01/2026",Tablo17106121316182022242[MÜŞTERİ ADI],'GİDER İCMAL'!A12) -> 0 | C12: =+SUMIFS(Tablo17106121316182022242[SATIŞ TUTARI],Tablo17106121316182022242[TARİH],">=01/02/2026",Tablo17106121316182022242[TARİH],"<=28/02/2026",Tablo17106121316182022242[MÜŞTERİ ADI],'GİDER İCMAL'!A12) -> 0 | N12: =+SUM(B12:M12) -> 0 | P12: =+N12-O12 -> 0
B13: =+SUMIFS(Tablo17106121316182022242[SATIŞ TUTARI],Tablo17106121316182022242[TARİH],">=01/01/2026",Tablo17106121316182022242[TARİH],"<=31/01/2026",Tablo17106121316182022242[MÜŞTERİ ADI],'GİDER İCMAL'!A13) -> 0 | C13: =+SUMIFS(Tablo17106121316182022242[SATIŞ TUTARI],Tablo17106121316182022242[TARİH],">=01/02/2026",Tablo17106121316182022242[TARİH],"<=28/02/2026",Tablo17106121316182022242[MÜŞTERİ ADI],'GİDER İCMAL'!A13) -> 0 | N13: =+SUM(B13:M13) -> 0 | P13: =+N13-O13 -> 0
B14: =+SUMIFS(Tablo17106121316182022242[SATIŞ TUTARI],Tablo17106121316182022242[TARİH],">=01/01/2026",Tablo17106121316182022242[TARİH],"<=31/01/2026",Tablo17106121316182022242[MÜŞTERİ ADI],'GİDER İCMAL'!A14) -> 0 | C14: =+SUMIFS(Tablo17106121316182022242[SATIŞ TUTARI],Tablo17106121316182022242[TARİH],">=01/02/2026",Tablo17106121316182022242[TARİH],"<=28/02/2026",Tablo17106121316182022242[MÜŞTERİ ADI],'GİDER İCMAL'!A14) -> 0 | N14: =+SUM(B14:M14) -> 0 | P14: =+N14-O14 -> 0
B15: =+SUMIFS(Tablo17106121316182022242[SATIŞ TUTARI],Tablo17106121316182022242[TARİH],">=01/01/2026",Tablo17106121316182022242[TARİH],"<=31/01/2026",Tablo17106121316182022242[MÜŞTERİ ADI],'GİDER İCMAL'!A15) -> 0 | C15: =+SUMIFS(Tablo17106121316182022242[SATIŞ TUTARI],Tablo17106121316182022242[TARİH],">=01/02/2026",Tablo17106121316182022242[TARİH],"<=28/02/2026",Tablo17106121316182022242[MÜŞTERİ ADI],'GİDER İCMAL'!A15) -> 0 | N15: =+SUM(B15:M15) -> 0 | P15: =+N15-O15 -> 0
... B121: =+SUMIFS(Tablo17106121316182022242[SATIŞ TUTARI],Tablo17106121316182022242[TARİH],">=01/01/2026",Tablo17106121316182022242[TARİH],"<=31/01/2026",Tablo17106121316182022242[MÜŞTERİ ADI],'GİDER İCMAL'!A121) -> 0 | C121: =+SUMIFS(Tablo17106121316182022242[SATIŞ TUTARI],Tablo17106121316182022242[TARİH],">=01/02/2026",Tablo17106121316182022242[TARİH],"<=28/02/2026",Tablo17106121316182022242[MÜŞTERİ ADI],'GİDER İCMAL'!A121) -> 0 | N121: =+SUM(B121:M121) -> 0 | P121: =+N121-O121 -> 0
B122: =SUM(B3:B121) -> 0 | C122: =SUM(C3:C121) -> 0 | D122: =SUM(D3:D121) -> 0 | E122: =SUM(E3:E121) -> 0 | F122: =SUM(F3:F121) -> 0 | G122: =SUM(G3:G121) -> 0 | H122: =SUM(H3:H121) -> 0 | I122: =SUM(I3:I121) -> 0 | ... O122: =SUM(O3:O121) -> 0 | P122: =+N122-O122 -> 0 | Q122: =SUM(Q3:Q121) -> 0 | R122: =SUM(R3:R121) -> 0 | S122: =SUM(S3:S121) -> 0 | T122: =SUM(T3:T121) -> 0 | U122: =SUM(U3:U121) -> 0 | V122: =SUM(V3:V121) -> 0 | W122: =SUM(W3:W121) -> 0 | X122: =SUM(X3:X121) -> 0 | ... AB122: =SUM(AB3:AB121) -> 0
P123: =+IF(Q123=P122,"HATA YOK","HATA VAR") -> HATA YOK | Q123: =+SUM(Q122:AB122) -> 0

Sheet GELEN İŞLER
A8: PLANAKS MÜHENDİSLİK MİMARLIK İNŞAAT PEYZAJ EMLAK SANAYİ VE TİCARET LİMİTED ŞİRKETİ GELEN İŞLER LİSTESİ
A9: TARİH | B9: DOSYA NO | C9: MÜŞTERİ ADI | D9: İŞİN ADI | E9: İŞİN TÜRÜ | F9: İŞİN DURUMU | G9: SATIŞ TUTARI | H9: ÖDENME DURUMU | I9: 1.NOT | J9: 2.NOT | K9: DOSYA ADI
A10: 46025 | B10: 20260101 | E10: AKUSTİK RAPOR & PROJE | F10: TESLİM EDİLDİ | H10: ÖDENMEDİ | K10: =+CONCATENATE(Tablo1710612131618202224[[#This Row],[DOSYA NO]],"_",Tablo1710612131618202224[[#This Row],[MÜŞTERİ ADI]],$P$10,"_",Tablo1710612131618202224[[#This Row],[İŞİN ADI]],"_",Tablo1710612131618202224[[#This Row],[İŞİN TÜRÜ]]) -> 20260101___AKUSTİK RAPOR & PROJE | M10: TESLİM EDİLDİ | N10: ÖDEME ALINDI
A11: 46025 | B11: 20260102 | E11: AKUSTİK RAPOR & PROJE | F11: TESLİM EDİLDİ | H11: ÖDENMEDİ | K11: =+CONCATENATE(Tablo1710612131618202224[[#This Row],[DOSYA NO]],"_",Tablo1710612131618202224[[#This Row],[MÜŞTERİ ADI]],$P$10,"_",Tablo1710612131618202224[[#This Row],[İŞİN ADI]],"_",Tablo1710612131618202224[[#This Row],[İŞİN TÜRÜ]]) -> 20260102___AKUSTİK RAPOR & PROJE | M11: DEVAM EDİYOR | N11: ÖDENMEDİ
A12: 46025 | B12: 20260103 | E12: AKUSTİK RAPOR & PROJE | F12: TESLİM EDİLDİ | H12: ÖDENMEDİ | K12: =+CONCATENATE(Tablo1710612131618202224[[#This Row],[DOSYA NO]],"_",Tablo1710612131618202224[[#This Row],[MÜŞTERİ ADI]],$P$10,"_",Tablo1710612131618202224[[#This Row],[İŞİN ADI]],"_",Tablo1710612131618202224[[#This Row],[İŞİN TÜRÜ]]) -> 20260103___AKUSTİK RAPOR & PROJE | M12: İPTAL EDİLDİ
A13: 46025 | B13: 20260104 | E13: ÖN HESAP SONUÇ FORMU | F13: TESLİM EDİLDİ | H13: ÖDENMEDİ | K13: =+CONCATENATE(Tablo1710612131618202224[[#This Row],[DOSYA NO]],"_",Tablo1710612131618202224[[#This Row],[MÜŞTERİ ADI]],$P$10,"_",Tablo1710612131618202224[[#This Row],[İŞİN ADI]],"_",Tablo1710612131618202224[[#This Row],[İŞİN TÜRÜ]]) -> 20260104___ÖN HESAP SONUÇ FORMU
A14: 46025 | B14: 20260105 | E14: EKB ÇİZİMİ | F14: İPTAL EDİLDİ | K14: =+CONCATENATE(Tablo1710612131618202224[[#This Row],[DOSYA NO]],"_",Tablo1710612131618202224[[#This Row],[MÜŞTERİ ADI]],$P$10,"_",Tablo1710612131618202224[[#This Row],[İŞİN ADI]],"_",Tablo1710612131618202224[[#This Row],[İŞİN TÜRÜ]]) -> 20260105___EKB ÇİZİMİ
A15: 46025 | B15: 20260106 | E15: EKB ÇİZİMİ | F15: TESLİM EDİLDİ | H15: ÖDENMEDİ | K15: =+CONCATENATE(Tablo1710612131618202224[[#This Row],[DOSYA NO]],"_",Tablo1710612131618202224[[#This Row],[MÜŞTERİ ADI]],$P$10,"_",Tablo1710612131618202224[[#This Row],[İŞİN ADI]],"_",Tablo1710612131618202224[[#This Row],[İŞİN TÜRÜ]]) -> 20260106___EKB ÇİZİMİ
A16: 46025 | B16: 20260107 | E16: ÖN HESAP SONUÇ FORMU | F16: TESLİM EDİLDİ | H16: ÖDENMEDİ | K16: =+CONCATENATE(Tablo1710612131618202224[[#This Row],[DOSYA NO]],"_",Tablo1710612131618202224[[#This Row],[MÜŞTERİ ADI]],$P$10,"_",Tablo1710612131618202224[[#This Row],[İŞİN ADI]],"_",Tablo1710612131618202224[[#This Row],[İŞİN TÜRÜ]]) -> 20260107___ÖN HESAP SONUÇ FORMU
A17: 46025 | B17: 20260108 | E17: EKB ÇİZİM VE ONAYI | F17: TESLİM EDİLDİ | H17: ÖDENMEDİ | K17: =+CONCATENATE(Tablo1710612131618202224[[#This Row],[DOSYA NO]],"_",Tablo1710612131618202224[[#This Row],[MÜŞTERİ ADI]],$P$10,"_",Tablo1710612131618202224[[#This Row],[İŞİN ADI]],"_",Tablo1710612131618202224[[#This Row],[İŞİN TÜRÜ]]) -> 20260108___EKB ÇİZİM VE ONAYI
A18: 46025 | B18: 20260109 | E18: ÖN HESAP SONUÇ FORMU | F18: TESLİM EDİLDİ | H18: ÖDENMEDİ | K18: =+CONCATENATE(Tablo1710612131618202224[[#This Row],[DOSYA NO]],"_",Tablo1710612131618202224[[#This Row],[MÜŞTERİ ADI]],$P$10,"_",Tablo1710612131618202224[[#This Row],[İŞİN ADI]],"_",Tablo1710612131618202224[[#This Row],[İŞİN TÜRÜ]]) -> 20260109___ÖN HESAP SONUÇ FORMU
A19: 46025 | B19: 20260110 | E19: AKUSTİK RAPOR & PROJE | F19: TESLİM EDİLDİ | H19: ÖDENMEDİ | K19: =+CONCATENATE(Tablo1710612131618202224[[#This Row],[DOSYA NO]],"_",Tablo1710612131618202224[[#This Row],[MÜŞTERİ ADI]],$P$10,"_",Tablo1710612131618202224[[#This Row],[İŞİN ADI]],"_",Tablo1710612131618202224[[#This Row],[İŞİN TÜRÜ]]) -> 20260110___AKUSTİK RAPOR & PROJE
A20: 46025 | B20: 20260111 | E20: EKB ÇİZİMİ | F20: TESLİM EDİLDİ | H20: ÖDENMEDİ | K20: =+CONCATENATE(Tablo1710612131618202224[[#This Row],[DOSYA NO]],"_",Tablo1710612131618202224[[#This Row],[MÜŞTERİ ADI]],$P$10,"_",Tablo1710612131618202224[[#This Row],[İŞİN ADI]],"_",Tablo1710612131618202224[[#This Row],[İŞİN TÜRÜ]]) -> 20260111___EKB ÇİZİMİ
A21: 46025 | B21: 20260112 | E21: EKB ÇİZİMİ | F21: TESLİM EDİLDİ | H21: ÖDENMEDİ | K21: =+CONCATENATE(Tablo1710612131618202224[[#This Row],[DOSYA NO]],"_",Tablo1710612131618202224[[#This Row],[MÜŞTERİ ADI]],$P$10,"_",Tablo1710612131618202224[[#This Row],[İŞİN ADI]],"_",Tablo1710612131618202224[[#This Row],[İŞİN TÜRÜ]]) -> 20260112___EKB ÇİZİMİ
A22: 46025 | B22: 20260113 | E22: EKB ÇİZİMİ | F22: TESLİM EDİLDİ | H22: ÖDENMEDİ | K22: =+CONCATENATE(Tablo1710612131618202224[[#This Row],[DOSYA NO]],"_",Tablo1710612131618202224[[#This Row],[MÜŞTERİ ADI]],$P$10,"_",Tablo1710612131618202224[[#This Row],[İŞİN ADI]],"_",Tablo1710612131618202224[[#This Row],[İŞİN TÜRÜ]]) -> 20260113___EKB ÇİZİMİ
A23: 46025 | B23: 20260114 | E23: ÖN HESAP SONUÇ FORMU | F23: TESLİM EDİLDİ | H23: ÖDENMEDİ | K23: =+CONCATENATE(Tablo1710612131618202224[[#This Row],[DOSYA NO]],"_",Tablo1710612131618202224[[#This Row],[MÜŞTERİ ADI]],$P$10,"_",Tablo1710612131618202224[[#This Row],[İŞİN ADI]],"_",Tablo1710612131618202224[[#This Row],[İŞİN TÜRÜ]]) -> 20260114___ÖN HESAP SONUÇ FORMU
A24: 46025 | B24: 20260115 | E24: AKUSTİK RAPOR & PROJE | F24: TESLİM EDİLDİ | H24: ÖDENMEDİ | K24: =+CONCATENATE(Tablo1710612131618202224[[#This Row],[DOSYA NO]],"_",Tablo1710612131618202224[[#This Row],[MÜŞTERİ ADI]],$P$10,"_",Tablo1710612131618202224[[#This Row],[İŞİN ADI]],"_",Tablo1710612131618202224[[#This Row],[İŞİN TÜRÜ]]) -> 20260115___AKUSTİK RAPOR & PROJE
A25: 46025 | B25: 20260116 | E25: EKB ÇİZİMİ | F25: TESLİM EDİLDİ | H25: ÖDENMEDİ | K25: =+CONCATENATE(Tablo1710612131618202224[[#This Row],[DOSYA NO]],"_",Tablo1710612131618202224[[#This Row],[MÜŞTERİ ADI]],$P$10,"_",Tablo1710612131618202224[[#This Row],[İŞİN ADI]],"_",Tablo1710612131618202224[[#This Row],[İŞİN TÜRÜ]]) -> 20260116___EKB ÇİZİMİ
A26: 46027 | B26: 20260117 | E26: EKB ÇİZİM VE ONAYI | F26: TESLİM EDİLDİ | H26: ÖDENMEDİ | K26: =+CONCATENATE(Tablo1710612131618202224[[#This Row],[DOSYA NO]],"_",Tablo1710612131618202224[[#This Row],[MÜŞTERİ ADI]],$P$10,"_",Tablo1710612131618202224[[#This Row],[İŞİN ADI]],"_",Tablo1710612131618202224[[#This Row],[İŞİN TÜRÜ]]) -> 20260117___EKB ÇİZİM VE ONAYI
... A53: 46029 | B53: 20260144 | E53: AKUSTİK RAPOR & PROJE | F53: TESLİM EDİLDİ | H53: ÖDENMEDİ | K53: =+CONCATENATE(Tablo1710612131618202224[[#This Row],[DOSYA NO]],"_",Tablo1710612131618202224[[#This Row],[MÜŞTERİ ADI]],$P$10,"_",Tablo1710612131618202224[[#This Row],[İŞİN ADI]],"_",Tablo1710612131618202224[[#This Row],[İŞİN TÜRÜ]]) -> 20260144___AKUSTİK RAPOR & PROJE
A54: 46029 | B54: 20260145 | E54: ÖN HESAP SONUÇ FORMU | F54: TESLİM EDİLDİ | H54: ÖDENMEDİ | I54: FATURA KESİLDİ | K54: =+CONCATENATE(Tablo1710612131618202224[[#This Row],[DOSYA NO]],"_",Tablo1710612131618202224[[#This Row],[MÜŞTERİ ADI]],$P$10,"_",Tablo1710612131618202224[[#This Row],[İŞİN ADI]],"_",Tablo1710612131618202224[[#This Row],[İŞİN TÜRÜ]]) -> 20260145___ÖN HESAP SONUÇ FORMU
A55: 46029 | B55: 20260146 | E55: EKB ÇİZİMİ | F55: TESLİM EDİLDİ | H55: ÖDENMEDİ | K55: =+CONCATENATE(Tablo1710612131618202224[[#This Row],[DOSYA NO]],"_",Tablo1710612131618202224[[#This Row],[MÜŞTERİ ADI]],$P$10,"_",Tablo1710612131618202224[[#This Row],[İŞİN ADI]],"_",Tablo1710612131618202224[[#This Row],[İŞİN TÜRÜ]]) -> 20260146___EKB ÇİZİMİ
A56: 46029 | B56: 20260147 | E56: ÖN HESAP SONUÇ FORMU | F56: TESLİM EDİLDİ | H56: ÖDENMEDİ | K56: =+CONCATENATE(Tablo1710612131618202224[[#This Row],[DOSYA NO]],"_",Tablo1710612131618202224[[#This Row],[MÜŞTERİ ADI]],$P$10,"_",Tablo1710612131618202224[[#This Row],[İŞİN ADI]],"_",Tablo1710612131618202224[[#This Row],[İŞİN TÜRÜ]]) -> 20260147___ÖN HESAP SONUÇ FORMU
A57: 46029 | B57: 20260148 | E57: AKUSTİK RAPOR & PROJE | F57: TESLİM EDİLDİ | H57: ÖDENMEDİ | K57: =+CONCATENATE(Tablo1710612131618202224[[#This Row],[DOSYA NO]],"_",Tablo1710612131618202224[[#This Row],[MÜŞTERİ ADI]],$P$10,"_",Tablo1710612131618202224[[#This Row],[İŞİN ADI]],"_",Tablo1710612131618202224[[#This Row],[İŞİN TÜRÜ]]) -> 20260148___AKUSTİK RAPOR & PROJE
A58: 46029 | B58: 20260149 | E58: EKB ÇİZİM VE ONAYI | F58: TESLİM EDİLDİ | H58: ÖDENMEDİ | K58: =+CONCATENATE(Tablo1710612131618202224[[#This Row],[DOSYA NO]],"_",Tablo1710612131618202224[[#This Row],[MÜŞTERİ ADI]],$P$10,"_",Tablo1710612131618202224[[#This Row],[İŞİN ADI]],"_",Tablo1710612131618202224[[#This Row],[İŞİN TÜRÜ]]) -> 20260149___EKB ÇİZİM VE ONAYI
A59: 46029 | B59: 20260150 | E59: EKB ÇİZİM VE ONAYI | F59: TESLİM EDİLDİ | H59: ÖDENMEDİ | K59: =+CONCATENATE(Tablo1710612131618202224[[#This Row],[DOSYA NO]],"_",Tablo1710612131618202224[[#This Row],[MÜŞTERİ ADI]],$P$10,"_",Tablo1710612131618202224[[#This Row],[İŞİN ADI]],"_",Tablo1710612131618202224[[#This Row],[İŞİN TÜRÜ]]) -> 20260150___EKB ÇİZİM VE ONAYI
A60: 46029 | B60: 20260151 | E60: EKB ONAYI | F60: TESLİM EDİLDİ | H60: ÖDEME ALINDI | K60: =+CONCATENATE(Tablo1710612131618202224[[#This Row],[DOSYA NO]],"_",Tablo1710612131618202224[[#This Row],[MÜŞTERİ ADI]],$P$10,"_",Tablo1710612131618202224[[#This Row],[İŞİN ADI]],"_",Tablo1710612131618202224[[#This Row],[İŞİN TÜRÜ]]) -> 20260151___EKB ONAYI
A61: 46029 | B61: 20260152 | E61: EKB ÇİZİMİ | F61: TESLİM EDİLDİ | H61: ÖDENMEDİ | K61: =+CONCATENATE(Tablo1710612131618202224[[#This Row],[DOSYA NO]],"_",Tablo1710612131618202224[[#This Row],[MÜŞTERİ ADI]],$P$10,"_",Tablo1710612131618202224[[#This Row],[İŞİN ADI]],"_",Tablo1710612131618202224[[#This Row],[İŞİN TÜRÜ]]) -> 20260152___EKB ÇİZİMİ
A62: 46029 | B62: 20260153 | E62: EKB ÇİZİM VE ONAYI | F62: TESLİM EDİLDİ | H62: ÖDENMEDİ | K62: =+CONCATENATE(Tablo1710612131618202224[[#This Row],[DOSYA NO]],"_",Tablo1710612131618202224[[#This Row],[MÜŞTERİ ADI]],$P$10,"_",Tablo1710612131618202224[[#This Row],[İŞİN ADI]],"_",Tablo1710612131618202224[[#This Row],[İŞİN TÜRÜ]]) -> 20260153___EKB ÇİZİM VE ONAYI
A63: 46029 | B63: 20260154 | E63: EKB ÇİZİMİ | F63: TESLİM EDİLDİ | H63: ÖDENMEDİ | K63: =+CONCATENATE(Tablo1710612131618202224[[#This Row],[DOSYA NO]],"_",Tablo1710612131618202224[[#This Row],[MÜŞTERİ ADI]],$P$10,"_",Tablo1710612131618202224[[#This Row],[İŞİN ADI]],"_",Tablo1710612131618202224[[#This Row],[İŞİN TÜRÜ]]) -> 20260154___EKB ÇİZİMİ
A64: 46029 | B64: 20260155 | E64: ÖN HESAP SONUÇ FORMU | F64: TESLİM EDİLDİ | H64: ÖDENMEDİ | K64: =+CONCATENATE(Tablo1710612131618202224[[#This Row],[DOSYA NO]],"_",Tablo1710612131618202224[[#This Row],[MÜŞTERİ ADI]],$P$10,"_",Tablo1710612131618202224[[#This Row],[İŞİN ADI]],"_",Tablo1710612131618202224[[#This Row],[İŞİN TÜRÜ]]) -> 20260155___ÖN HESAP SONUÇ FORMU
A65: 46029 | B65: 20260156 | E65: AKUSTİK RAPOR & PROJE | F65: TESLİM EDİLDİ | H65: ÖDENMEDİ | K65: =+CONCATENATE(Tablo1710612131618202224[[#This Row],[DOSYA NO]],"_",Tablo1710612131618202224[[#This Row],[MÜŞTERİ ADI]],$P$10,"_",Tablo1710612131618202224[[#This Row],[İŞİN ADI]],"_",Tablo1710612131618202224[[#This Row],[İŞİN TÜRÜ]]) -> 20260156___AKUSTİK RAPOR & PROJE
A66: 46029 | B66: 20260157 | E66: AKUSTİK RAPOR & PROJE | F66: TESLİM EDİLDİ | H66: ÖDENMEDİ | K66: =+CONCATENATE(Tablo1710612131618202224[[#This Row],[DOSYA NO]],"_",Tablo1710612131618202224[[#This Row],[MÜŞTERİ ADI]],$P$10,"_",Tablo1710612131618202224[[#This Row],[İŞİN ADI]],"_",Tablo1710612131618202224[[#This Row],[İŞİN TÜRÜ]]) -> 20260157___AKUSTİK RAPOR & PROJE
... A68: 46029 | B68: 20260159 | E68: EKB ÇİZİMİ | F68: TESLİM EDİLDİ | H68: ÖDENMEDİ | K68: =+CONCATENATE(Tablo1710612131618202224[[#This Row],[DOSYA NO]],"_",Tablo1710612131618202224[[#This Row],[MÜŞTERİ ADI]],$P$10,"_",Tablo1710612131618202224[[#This Row],[İŞİN ADI]],"_",Tablo1710612131618202224[[#This Row],[İŞİN TÜRÜ]]) -> 20260159___EKB ÇİZİMİ
A69: 46029 | B69: 20260160 | E69: EKB ÇİZİMİ | F69: TESLİM EDİLDİ | H69: ÖDENMEDİ | I69: GESSİZ İŞ | K69: =+CONCATENATE(Tablo1710612131618202224[[#This Row],[DOSYA NO]],"_",Tablo1710612131618202224[[#This Row],[MÜŞTERİ ADI]],$P$10,"_",Tablo1710612131618202224[[#This Row],[İŞİN ADI]],"_",Tablo1710612131618202224[[#This Row],[İŞİN TÜRÜ]]) -> 20260160___EKB ÇİZİMİ
A70: 46029 | B70: 20260161 | E70: ÖN HESAP SONUÇ FORMU | F70: TESLİM EDİLDİ | H70: ÖDENMEDİ | K70: =+CONCATENATE(Tablo1710612131618202224[[#This Row],[DOSYA NO]],"_",Tablo1710612131618202224[[#This Row],[MÜŞTERİ ADI]],$P$10,"_",Tablo1710612131618202224[[#This Row],[İŞİN ADI]],"_",Tablo1710612131618202224[[#This Row],[İŞİN TÜRÜ]]) -> 20260161___ÖN HESAP SONUÇ FORMU
A71: 46030 | B71: 20260162 | E71: EKB ONAYI | F71: TESLİM EDİLDİ | H71: ÖDEME ALINDI | J71: İKİ DEFA ONAY YAPILDI | K71: =+CONCATENATE(Tablo1710612131618202224[[#This Row],[DOSYA NO]],"_",Tablo1710612131618202224[[#This Row],[MÜŞTERİ ADI]],$P$10,"_",Tablo1710612131618202224[[#This Row],[İŞİN ADI]],"_",Tablo1710612131618202224[[#This Row],[İŞİN TÜRÜ]]) -> 20260162___EKB ONAYI
A72: 46030 | B72: 20260163 | E72: ÖN HESAP SONUÇ FORMU | F72: TESLİM EDİLDİ | H72: ÖDENMEDİ | K72: =+CONCATENATE(Tablo1710612131618202224[[#This Row],[DOSYA NO]],"_",Tablo1710612131618202224[[#This Row],[MÜŞTERİ ADI]],$P$10,"_",Tablo1710612131618202224[[#This Row],[İŞİN ADI]],"_",Tablo1710612131618202224[[#This Row],[İŞİN TÜRÜ]]) -> 20260163___ÖN HESAP SONUÇ FORMU
A73: 46030 | B73: 20260164 | E73: AKUSTİK RAPOR & PROJE | F73: TESLİM EDİLDİ | H73: ÖDENMEDİ | K73: =+CONCATENATE(Tablo1710612131618202224[[#This Row],[DOSYA NO]],"_",Tablo1710612131618202224[[#This Row],[MÜŞTERİ ADI]],$P$10,"_",Tablo1710612131618202224[[#This Row],[İŞİN ADI]],"_",Tablo1710612131618202224[[#This Row],[İŞİN TÜRÜ]]) -> 20260164___AKUSTİK RAPOR & PROJE
A74: 46030 | B74: 20260165 | E74: ÖN HESAP SONUÇ FORMU | F74: TESLİM EDİLDİ | H74: ÖDENMEDİ | K74: =+CONCATENATE(Tablo1710612131618202224[[#This Row],[DOSYA NO]],"_",Tablo1710612131618202224[[#This Row],[MÜŞTERİ ADI]],$P$10,"_",Tablo1710612131618202224[[#This Row],[İŞİN ADI]],"_",Tablo1710612131618202224[[#This Row],[İŞİN TÜRÜ]]) -> 20260165___ÖN HESAP SONUÇ FORMU
...

Sheet GİDEN İŞLER
A8: PLANAKS MÜHENDİSLİK MİMARLIK İNŞAAT PEYZAJ EMLAK SANAYİ VE TİCARET LİMİTED ŞİRKETİ GİDEN İŞLER LİSTESİ
A9: TARİH | B9: DOSYA NO | C9: MÜŞTERİ ADI | D9: İŞİN ADI | E9: İŞİN TÜRÜ | F9: İŞİN DURUMU | G9: SATIŞ TUTARI | H9: ÖDENME DURUMU | I9: HARÇ ÜCRETİ | J9: 2.NOT | K9: 3.NOT
A10: 46028 | B10: 20260108 | D10: SABAHATTİN KARAMAN VE HİSS | E10: EKB ONAYI | F10: TESLİM EDİLDİ | H10: ÖDENMEDİ | I10: 378.45 | M10: TESLİM EDİLDİ | N10: ÖDEME ALINDI
A11: 46028 | B11: 20260117 | D11: SAFİYE ÖZTÜRK | E11: EKB ONAYI | F11: TESLİM EDİLDİ | H11: ÖDENMEDİ | I11: 359.7 | M11: DEVAM EDİYOR | N11: ÖDENMEDİ
A12: 46028 | B12: 20260118 | D12: GAMZE YILDIZ | E12: EKB ONAYI | F12: TESLİM EDİLDİ | H12: ÖDENMEDİ | I12: 399.6 | M12: İPTAL EDİLDİ
A13: 46028 | B13: 20260119 | D13: MAHSUN TUNÇ | E13: EKB ONAYI | F13: TESLİM EDİLDİ | H13: ÖDENMEDİ | I13: 452.7
A14: 46028 | B14: 20260120 | D14: SEMİH YETER VE HİSS | E14: EKB ONAYI | F14: TESLİM EDİLDİ | H14: ÖDENMEDİ | I14: 364.05
A15: 46028 | B15: 20260121 | D15: SELAMİ YÜCEHAN VE HİSS | E15: EKB ONAYI | F15: TESLİM EDİLDİ | H15: ÖDENMEDİ | I15: 482.4
A16: 46028 | B16: 20260122 | D16: ORKUN SELVİ | E16: EKB ONAYI | F16: TESLİM EDİLDİ | H16: ÖDENMEDİ | I16: 445.2
A17: 46028 | B17: 20260123 | D17: KEMAL KAYA VE HİSS | E17: EKB ONAYI | F17: TESLİM EDİLDİ | H17: ÖDENMEDİ | I17: 496.1
A18: 46029 | B18: 20260149 | D18: ADIYAMAN 63 BLOK TOKİ | E18: EKB ONAYI | F18: TESLİM EDİLDİ | H18: ÖDENMEDİ | I18: 13176.9
A19: 46029 | B19: 20260151 | D19: DARÜLACEZE 11 BLOK | E19: EKB ONAYI | F19: TESLİM EDİLDİ | H19: ÖDENMEDİ | I19: 6534.55
A20: 46030 | B20: 20260153 | D20: MUSTAFAPAŞA ASM | E20: EKB ONAYI | F20: TESLİM EDİLDİ | H20: ÖDENMEDİ | I20: 453.15
A21: 46030 | B21: 20260162 | D21: ERDOĞAN GÜL - ERSİN ŞİMŞİR | E21: EKB ONAYI | F21: TESLİM EDİLDİ | H21: ÖDENMEDİ | I21: =495.9+480.3 -> 976.2 | J21: İKİ DEFA ONAY YAPILDI
A22: 46031 | B22: 20260173 | D22: KEMAL SEYFİ | E22: EKB ONAYI | F22: TESLİM EDİLDİ | H22: ÖDENMEDİ | I22: 360.8
A23: 46031 | B23: 20260174 | D23: ESAT SARA VE ORT | E23: EKB ONAYI | F23: TESLİM EDİLDİ | H23: ÖDENMEDİ | I23: 330.8
A24: 46032 | B24: 20260150 | D24: ÇAĞLAYANCERİT 4 BLOK TOKİ | E24: EKB ONAYI | F24: TESLİM EDİLDİ | H24: ÖDENMEDİ | I24: =589.2*4 -> 2356.8
A25: 46035 | B25: 202601118 | D25: MUSTAFA HARUN GÜMÜŞEL | E25: EKB ONAYI | F25: BEKLEMEDE | H25: ÖDENMEDİ | I25: =397.5+345+455 -> 1197.5
A26: 46035 | B26: 202601121 | D26: MUHAMMED FATİH BAHÇECİ | E26: EKB ONAYI | F26: TESLİM EDİLDİ | H26: ÖDENMEDİ | I26: 572.7
A27: 46035 | B27: 202601122 | D27: ABDULLAH ALAŞ | E27: EKB ONAYI | F27: TESLİM EDİLDİ | H27: ÖDENMEDİ | I27: 352.5
A28: 46036 | B28: 202601145 | D28: AFYON TOKİ 2 BLOK | E28: EKB ONAYI | F28: TESLİM EDİLDİ | H28: ÖDENMEDİ | I28: =529.8+529.8 -> 1059.6
A29: 46036 | B29: 202601146 | D29: ALİ MUTLU 1565-12 | E29: 3BSYM | F29: TESLİM EDİLDİ | H29: ÖDENMEDİ
A30: 46036 | B30: 202601130 | D30: ERGANİ İLÇE TARIM MÜDÜRLÜĞÜ | E30: EKB ONAYI | F30: TESLİM EDİLDİ | H30: ÖDENMEDİ | I30: 534.4
A31: 46037 | B31: 202601144 | D31: TOBB 3 BLOK | E31: EKB ONAYI | F31: TESLİM EDİLDİ | H31: ÖDENMEDİ | I31: =780.3+768.8+470 -> 2019.1
A32: 46037 | B32: 202601161 | D32: MEHMET ZÜLFÜ GENÇ | E32: EKB ONAYI | F32: TESLİM EDİLDİ | H32: ÖDENMEDİ | I32: 399.75
A33: 46037 | B33: 202601162 | D33: YUNUS AYTEMUR - ABDULLAH AYTEMUR | E33: EKB ONAYI | F33: TESLİM EDİLDİ | H33: ÖDENMEDİ | I33: =372+361.1 -> 733.1
A34: 46038 | B34: 202601159 | D34: BİZMİŞEN 1.ETAP 571 KONUT 29 BLOK | E34: EKB ONAYI | F34: TESLİM EDİLDİ | H34: ÖDENMEDİ | I34: 17981.3 | J34: HARÇLARI BEN ÖDEYECEM
A35: 46038 | B35: 202601165 | D35: HACI AHMET AYDIN VE MÜŞT | E35: EKB ONAYI | F35: İPTAL EDİLDİ
A36: 46041 | B36: 202601181 | D36: VEDAT ÇADIR VE HİSS | E36: EKB ONAYI | F36: İPTAL EDİLDİ
A37: 46041 | B37: 202601193 | D37: SERVET KALKAN | E37: EKB ONAYI | F37: TESLİM EDİLDİ | H37: ÖDENMEDİ | I37: 494.4
A38: 46042 | B38: 20260177 | D38: EMİNE KÖROĞLU | E38: EKB ONAYI | F38: TESLİM EDİLDİ | H38: ÖDENMEDİ | I38: 654.9
A39: 46042 | B39: 20260178 | D39: MEHRİ SAĞIR | E39: EKB ONAYI | F39: TESLİM EDİLDİ | H39: ÖDENMEDİ | I39: 357
A40: 46042 | B40: 202601215 | D40: CELAL BOZKURT | E40: EKB ONAYI | F40: TESLİM EDİLDİ | H40: ÖDENMEDİ | I40: 441.4
A41: 46042 | B41: 202601216 | D41: MUSTAFA YERLİ | E41: EKB ONAYI | F41: TESLİM EDİLDİ | H41: ÖDENMEDİ | I41: 438.4 | J41: HARCI BEN ÖDEDİM
A42: 46042 | B42: 202601217 | D42: DOĞAN EK | E42: EKB ONAYI | F42: BEKLEMEDE | H42: ÖDENMEDİ | I42: 504.5
A43: 46042 | B43: 202601218 | D43: NEZAKET DOĞAN VE HİSS | E43: EKB ONAYI | F43: TESLİM EDİLDİ | H43: ÖDENMEDİ | I43: 497.8
A44: 46042 | B44: 202601222 | D44: GÜLDEREN ERGEZER VE HİSS | E44: EKB ONAYI | F44: TESLİM EDİLDİ | H44: ÖDENMEDİ | I44: 500.7
A45: 46042 | B45: 202601223 | D45: RECEP BAŞPINAR VE HİSS | E45: EKB ONAYI | F45: TESLİM EDİLDİ | H45: ÖDENMEDİ | I45: 503
A46: 46043 | B46: 202601234 | D46: HİKMET ÇEÇEN | E46: EKB ONAYI | F46: TESLİM EDİLDİ | H46: ÖDENMEDİ | I46: 400.5
A47: 46045 | B47: 202601247 | D47: CÜNEYT TUNÇ AKASYA PARK | E47: EKB ONAYI | F47: TESLİM EDİLDİ | H47: ÖDENMEDİ | I47: 473.5
...

Sheet EKB HİZMET BEDELİ 2026
G1: ENERJİ KİMLİK BELGESİ HİZMET BEDELİ HESAPLANMASI | O1: NOT: YEŞİL DOLGULU OLAN YERE TOPLAM YAPI İNŞAAT ALANINI GİRİNİZ
A2: EKB HİZMET BEDELİ HESAPLAMA | G2: İNŞAAT ALANI | H2: KAT SAYI | I2: İNŞAAT ALANI | J2: TUTAR | L2: İNŞAAT ALANI | M2: KAT SAYI
A3: 0 | B3: 250 | C3: 0.3 | D3: 250 | E3: =D3*C3 -> 75 | G3: 0-250 m² arası | H3: 0.3 | J3: =+H3*I3 -> 0 | L3: 0-250 m² arası | M3: 0.3 | O3: 0-250 m² | Q3: =IF(P3="0,00 TL","",M3*P3)*1.25+300 -> 300
A4: 250 | B4: 500 | C4: 0.15 | D4: 250 | E4: =D4*C4 -> 37.5 | G4: 250-500 m² arası | H4: 0.15 | J4: =+H4*I4 -> 0 | L4: 250-500 m² arası | M4: 0.15 | O4: 250-500 m² | Q4: =+IF(P4="","0,00 TL",(((((250*M3)+(P4-250)*M4))*1.25)+300)) -> 0,00 TL
A5: 500 | B5: 1000 | C5: 0.1 | D5: 500 | E5: =D5*C5 -> 50 | G5: 500-1000 m² arası | H5: 0.1 | J5: =+H5*I5 -> 0 | L5: 500-1000 m² arası | M5: 0.1 | O5: 500-1000 m² | Q5: =IF(P5="","0,00 TL",(((250*M3)+(250*M4)+(P5-500)*M5)*1.25+300)) -> 0,00 TL
A6: 1000 | B6: 2000 | C6: 0.05 | D6: 1000 | E6: =D6*C6 -> 50 | G6: 1000-2000 m² arası | H6: 0.05 | J6: =+H6*I6 -> 0 | L6: 1000-2000 m² arası | M6: 0.05 | O6: 1000-2000 m² | Q6: =IF(P6="","0,00 TL",(((250*M3)+(250*M4)+(500*M5)+(P6-1000)*M6)*1.25+300)) -> 0,00 TL
A7: 2000 | B7: 5000 | C7: 0.04 | D7: 3000 | E7: =D7*C7 -> 120 | G7: 2000-5000 m² arası | H7: 0.04 | J7: =+H7*I7 -> 0 | L7: 2000-5000 m² arası | M7: 0.04 | O7: 2000-5000 m² | Q7: =+IF(P7="","0,00 TL",(((250*M3)+(250*M4)+(500*M5)+(1000*M6)+(P7-2000)*M7)*1.25+300)) -> 0,00 TL
A8: 5000 | B8: 10000 | C8: 0.03 | D8: 1163 | E8: =D8*C8 -> 34.89 | G8: 5000-10000 m² arası | H8: 0.03 | J8: =+H8*I8 -> 0 | L8: 5000-10000 m² arası | M8: 0.03 | O8: 5000-10000 m² | Q8: =+IF(P8="","0,00 TL",((((250*M3)+(250*M4)+(500*M5)+(1000*M6)+(3000*M7)+(P8-5000)*M8))*1.25+300)) -> 0,00 TL
A9: 10000 | B9: 50000 | C9: 0.02 | E9: =D9*C9 -> 0 | G9: 10000-50000 m² arası | H9: 0.02 | J9: =+H9*I9 -> 0 | L9: 10000-50000 m² arası | M9: 0.02 | O9: 10000-50000 m² | Q9: =+IF(P9="","0,00 TL",(((250*M3)+(250*M4)+(500*M5)+(1000*M6)+(3000*M7)+(5000*M8)+(P9-10000)*M9)*1.25+300)) -> 0,00 TL
A10: 50000 | B10: + | C10: 0.01 | E10: =D10*C10 -> 0 | G10: 50000 m² ve üzeri | H10: 0.01 | J10: =+H10*I10 -> 0 | L10: 50000 m² ve üzeri | M10: 0.01 | O10: 50000 m² ve üzeri | Q10: =+IF(P10="","0,00 TL",(((250*M3)+(250*M4)+(500*M5)+(1000*M6)+(3000*M7)+(5000*M8)+(40000*M9)+(P10-50000)*M10)*1.25+300)) -> 0,00 TL
A11: TOPLAM YAPI İNŞAAT ALANI | D11: =SUM(D3:D10) -> 6163 | G11: TOPLAM YAPI İNŞAAT ALANI : | I11: =SUM(I3:I10) -> 0
A12: TOPLAM REFERANS HİZMET BEDELİ | E12: =SUM(E3:E10) -> 367.39 | G12: TOPLAM REFERANS HİZMET BEDELİ : | J12: =SUM(J3:J11) -> 0

Sheet YEMEK TAKİBİ
A2: YEMEK FİRMASI | B2: HARPUT YEMEK | AJ2: KAHVALTI | AK2: 110 | AL2: KDV DAHİL
A3: YETKİLİ | B3: MAHMUT BEY | AJ3: ÖĞLE YEMEĞİ | AK3: 140 | AL3: KDV DAHİL
A4: GSM | B4: 5396017223 | AJ4: AKŞAM YEMEĞİ | AK4: 140 | AL4: KDV DAHİL
D7: 46023 | E7: 46023 | F7: 46024 | G7: 46025 | H7: 46026 | I7: 46027 | J7: 46028 | K7: 46029 | L7: 46030 | M7: 46031 | N7: 46032 | O7: 46033 | P7: 46034 | Q7: 46035 | R7: 46036 | S7: 46037 | T7: 46038 | U7: 46039 | V7: 46040 | W7: 46041 | X7: 46042 | Y7: 46043 | Z7: 46044 | AA7: 46045 | AB7: 46046 | AC7: 46047 | AD7: 46048 | AE7: 46049 | AF7: 46050 | AG7: 46051 | AH7: 46052 | AI7: 46053 | AJ7: TOPLAM | AK7: BİRİM FİYAT (KDV DAHİL) | AL7: TOPLAM TUTAR
D8: KAHVALTI | AJ8: =+SUM(E8:AI8) -> 0 | AK8: 110 | AL8: =+AJ8*AK8 -> 0
D9: ÖĞLE | AJ9: =+SUM(E9:AI9) -> 0 | AK9: 140 | AL9: =+AJ9*AK9 -> 0
D10: AKŞAM | AJ10: =+SUM(E10:AI10) -> 0 | AK10: 140 | AL10: =+AJ10*AK10 -> 0
D11: OCAK 2026 GENEL TOPLAM : | AL11: =SUM(AL8:AL10) -> 0
D13: 46054 | E13: 46054 | F13: 46055 | G13: 46056 | H13: 46057 | I13: 46058 | J13: 46059 | K13: 46060 | L13: 46061 | M13: 46062 | N13: 46063 | O13: 46064 | P13: 46065 | Q13: 46066 | R13: 46067 | S13: 46068 | T13: 46069 | U13: 46070 | V13: 46071 | W13: 46072 | X13: 46073 | Y13: 46074 | Z13: 46075 | AA13: 46076 | AB13: 46077 | AC13: 46078 | AD13: 46079 | AE13: 46080 | AF13: 46081 | AJ13: TOPLAM | AK13: BİRİM FİYAT (KDV DAHİL) | AL13: TOPLAM TUTAR
D14: KAHVALTI | AJ14: =+SUM(E14:AI14) -> 0 | AL14: =+AJ14*AK14 -> 0
D15: ÖĞLE | AJ15: =+SUM(E15:AI15) -> 0 | AL15: =+AJ15*AK15 -> 0
D16: AKŞAM | AJ16: =+SUM(E16:AI16) -> 0 | AL16: =+AJ16*AK16 -> 0
D17: ŞUBAT 2026 GENEL TOPLAM : | AL17: =SUM(AL14:AL16) -> 0
D19: 46082 | E19: 46082 | F19: 46083 | G19: 46084 | H19: 46085 | I19: 46086 | J19: 46087 | K19: 46088 | L19: 46089 | M19: 46090 | N19: 46091 | O19: 46092 | P19: 46093 | Q19: 46094 | R19: 46095 | S19: 46096 | T19: 46097 | U19: 46098 | V19: 46099 | W19: 46100 | X19: 46101 | Y19: 46102 | Z19: 46103 | AA19: 46104 | AB19: 46105 | AC19: 46106 | AD19: 46107 | AE19: 46108 | AF19: 46109 | AG19: 46110 | AH19: 46111 | AI19: 46112 | AJ19: TOPLAM | AK19: BİRİM FİYAT (KDV DAHİL) | AL19: TOPLAM TUTAR
D20: KAHVALTI | AJ20: =+SUM(E20:AI20) -> 0 | AL20: =+AJ20*AK20 -> 0
D21: ÖĞLE | AJ21: =+SUM(E21:AI21) -> 0 | AL21: =+AJ21*AK21 -> 0
D22: AKŞAM | AJ22: =+SUM(E22:AI22) -> 0 | AL22: =+AJ22*AK22 -> 0
D23: MART 2026 GENEL TOPLAM : | AL23: =SUM(AL20:AL22) -> 0
D25: 46113 | E25: 46113 | F25: 46114 | G25: 46115 | H25: 46116 | I25: 46117 | J25: 46118 | K25: 46119 | L25: 46120 | M25: 46121 | N25: 46122 | O25: 46123 | P25: 46124 | Q25: 46125 | R25: 46126 | S25: 46127 | T25: 46128 | U25: 46129 | V25: 46130 | W25: 46131 | X25: 46132 | Y25: 46133 | Z25: 46134 | AA25: 46135 | AB25: 46136 | AC25: 46137 | AD25: 46138 | AE25: 46139 | AF25: 46140 | AG25: 46141 | AH25: 46142 | AJ25: TOPLAM | AK25: BİRİM FİYAT (KDV DAHİL) | AL25: TOPLAM TUTAR
D26: KAHVALTI | AJ26: =+SUM(E26:AI26) -> 0 | AL26: =+AJ26*AK26 -> 0
D27: ÖĞLE | AJ27: =+SUM(E27:AI27) -> 0 | AL27: =+AJ27*AK27 -> 0
D28: AKŞAM | AJ28: =+SUM(E28:AI28) -> 0 | AL28: =+AJ28*AK28 -> 0
D29: NİSAN 2026 GENEL TOPLAM : | AL29: =SUM(AL26:AL28) -> 0
D31: 46143 | E31: 46143 | F31: 46144 | G31: 46145 | H31: 46146 | I31: 46147 | J31: 46148 | K31: 46149 | L31: 46150 | M31: 46151 | N31: 46152 | O31: 46153 | P31: 46154 | Q31: 46155 | R31: 46156 | S31: 46157 | T31: 46158 | U31: 46159 | V31: 46160 | W31: 46161 | X31: 46162 | Y31: 46163 | Z31: 46164 | AA31: 46165 | AB31: 46166 | AC31: 46167 | AD31: 46168 | AE31: 46169 | AF31: 46170 | AG31: 46171 | AH31: 46172 | AI31: 46173 | AJ31: TOPLAM | AK31: BİRİM FİYAT (KDV DAHİL) | AL31: TOPLAM TUTAR
D32: KAHVALTI | AJ32: =+SUM(E32:AI32) -> 0 | AL32: =+AJ32*AK32 -> 0
D33: ÖĞLE | AJ33: =+SUM(E33:AI33) -> 0 | AL33: =+AJ33*AK33 -> 0
D34: AKŞAM | AJ34: =+SUM(E34:AI34) -> 0 | AL34: =+AJ34*AK34 -> 0
D35: MAYIS 2026 GENEL TOPLAM : | AL35: =SUM(AL32:AL34) -> 0
